File: SQUID-Fix/Data_Files/eicosane.txt
[Header]
TITLE,MPMS RSO Measurement
BYAPP,MPMS Measurement,1.1,Summary
FILEOPENTIME, 1369560420.078000 5/26/2013, 10:27:00 AM

INFO, APPNAME, MPMS MultiVu Application, Revision 1.56,  Build 67

INFO, NAME, JPSW-RM-5
INFO, WEIGHT, 9.850
INFO, AREA, 1.000
INFO, LENGTH, 1.000
INFO, SHAPE, 0
INFO, COMMENT, JPSW, 13.19 mg eico
INFO, SEQUENCE FILE: Chi_T_Mag_RSO_rapid.seq


INFO, BACKGROUND DATA FILE:, None


STARTUPAXIS,X,4,LINEAR,AUTO,0.000000,0.000000
STARTUPAXIS,Y1,5,LINEAR,AUTO,0.000000,0.000000


STARTUPGROUP,Longitudinal
FIELDGROUP,Longitudinal,1,2,3,4,5,6,7,8,9,10,11,19,20,21,22,23,35
FIELDGROUP,Transverse,1,2,3,4,12,13,14,15,16,17,18,24,25,26,27,28,35

PLOT_APPEARANCE,ALL,HORZ_GRID_ON,VERT_GRID_ON,MARKERS_AND_LINES

[Data]
Temperature (K),Long Moment (emu),
300.0073,-3.85095E-5
290.2065,-3.84723E-5
280.0525,-3.84725E-5
269.59,-3.84572E-5
259.576,-3.84523E-5
249.6128,-3.8446E-5
239.6039,-3.84284E-5
229.656,-3.84251E-5
219.6075,-3.84035E-5
209.6649,-3.83955E-5
200.0095,-3.8367E-5
189.8245,-3.835E-5
179.7657,-3.83346E-5
169.825,-3.83036E-5
159.9261,-3.82929E-5
149.9022,-3.82808E-5
139.9376,-3.82435E-5
129.9435,-3.82247E-5
119.9715,-3.82134E-5
109.9962,-3.81829E-5
100.0046,-3.81691E-5
90.03703,-3.81366E-5
80.01647,-3.80874E-5
75.0539,-3.80829E-5
70.06837,-3.80568E-5
65.06059,-3.80195E-5
60.06941,-3.80031E-5
55.06784,-3.79779E-5
50.04877,-3.7938E-5
45.01579,-3.79119E-5
40.00419,-3.78552E-5
34.99456,-3.77976E-5
29.99442,-3.77068E-5
27.98761,-3.76716E-5
25.99094,-3.76228E-5
24.02978,-3.7564E-5
21.99895,-3.74972E-5
20.00061,-3.74093E-5
18.02399,-3.73304E-5
16.02115,-3.72012E-5
15.01154,-3.71189E-5
14.00965,-3.70474E-5
13.00906,-3.69398E-5
12.00741,-3.68284E-5
11.00945,-3.67149E-5
10.00503,-3.65554E-5
9.00649,-3.63606E-5
8.00759,-3.61299E-5
7.00894,-3.58485E-5
6.00407,-3.54952E-5
5.504,-3.52494E-5
5.00319,-3.4975E-5
4.5147,-3.45807E-5
4.00253,-3.41633E-5
3.49655,-3.36867E-5
3.00006,-3.30777E-5
2.49943,-3.2299E-5
1.99655,-3.10127E-5