File: SQUID-Fix/Data_Files/gelcap.txt
[Header]
TITLE,MPMS RSO Measurement
BYAPP,MPMS Measurement,1.1,Summary
FILEOPENTIME, 1369560420.078000 5/26/2013, 10:27:00 AM

INFO, APPNAME, MPMS MultiVu Application, Revision 1.56,  Build 67

INFO, NAME, JPSW-RM-5
INFO, WEIGHT, 9.850
INFO, AREA, 1.000
INFO, LENGTH, 1.000
INFO, SHAPE, 0
INFO, COMMENT, JPSW, 13.19 mg eico
INFO, SEQUENCE FILE: Chi_T_Mag_RSO_rapid.seq


INFO, BACKGROUND DATA FILE:, None


STARTUPAXIS,X,4,LINEAR,AUTO,0.000000,0.000000
STARTUPAXIS,Y1,5,LINEAR,AUTO,0.000000,0.000000


STARTUPGROUP,Longitudinal
FIELDGROUP,Longitudinal,1,2,3,4,5,6,7,8,9,10,11,19,20,21,22,23,35
FIELDGROUP,Transverse,1,2,3,4,12,13,14,15,16,17,18,24,25,26,27,28,35

PLOT_APPEARANCE,ALL,HORZ_GRID_ON,VERT_GRID_ON,MARKERS_AND_LINES

[Data]
Temperature (K),Long Moment (emu),
300.5603,-1.754977E-5
290.5461,-1.743607E-5
280.5584,-1.745928E-5
270.5602,-1.7423E-5
260.5403,-1.753693E-5
250.5174,-1.743918E-5
240.5209,-1.736317E-5
230.5182,-1.74431E-5
220.4964,-1.745137E-5
210.4757,-1.741229E-5
200.4567,-1.741553E-5
190.4484,-1.730667E-5
180.4215,-1.741627E-5
170.4021,-1.737639E-5
160.3795,-1.729953E-5
149.991,-1.72111E-5
140.3279,-1.726732E-5
130.3022,-1.723261E-5
120.2745,-1.717332E-5
110.2365,-1.727549E-5
100.2033,-1.722505E-5
90.18678,-1.70926E-5
80.12561,-1.72039E-5
75.10074,-1.718123E-5
70.08175,-1.705952E-5
65.08627,-1.700136E-5
60.05639,-1.709641E-5
55.02068,-1.697388E-5
50.02217,-1.686967E-5
45.00913,-1.679906E-5
40.00146,-1.668742E-5
34.99866,-1.660353E-5
30.0014,-1.650285E-5
27.9954,-1.637548E-5
25.99574,-1.635984E-5
23.98602,-1.632383E-5
21.98747,-1.613087E-5
19.98709,-1.605677E-5
17.98879,-1.585861E-5
15.98999,-1.567555E-5
14.00307,-1.553163E-5
12.9958,-1.540266E-5
11.99436,-1.527352E-5
10.99124,-1.506603E-5
10.00098,-1.498321E-5
8.997588,-1.474404E-5
8.004623,-1.441196E-5
7.003155,-1.412523E-5
5.990597,-1.368892E-5
5.504799,-1.347048E-5
5.005497,-1.314011E-5
4.501853,-1.288861E-5
4.00416,-1.25632E-5
3.49395,-1.203701E-5
2.997837,-1.146245E-5
2.496913,-1.07568E-5
1.99805,-9.723469E-6